Workbook

Sheet Léeme
A1: Hoja de parámetros del generador de datos sintéticos (Objetivo 1)
A2: Modelo predictivo con datos sintéticos para la estimación de tiempos y la asignación de recursos en laboratorios de control de calidad farmacéuticos
A4: Para qué sirve | B4: Reúne los parámetros operativos que reportan las cinco fuentes de calibración del anteproyecto, cada uno con su página, para construir el generador (bloques del 25 al 31 de octubre) y para la tabla de trazabilidad que arma Aldair el jueves 29.
A5: Hojas | B5: Parámetros (lista completa) · Duraciones (tres puntos por técnica y tarea, con media y desviación PERT) · Demanda (mezcla, volumen y escenarios de carga) · Catálogo (12 métodos: complejidad, soluciones, calificación mínima, participación, corrida, reanálisis y tipos de muestra) · Calibración del catálogo (cómo salen esas columnas de las fuentes) · Tipos de muestra (5 tipos: proporción, llegadas, plazo, prioridad, urgentes y probabilidad de cada método) · Calibración de tipos (cómo se reparte cada método entre los tipos sin cambiar la mezcla de técnicas) · Equipos (10 configuraciones: cantidad y compatibilidad con cada método) · Analistas (20 analistas: turno, nivel, área y matriz de calificación) · Calibración de recursos (horas de equipo, cobertura y chequeos) · Turnos (horario de cada código de turno) · Rotación (calendario de 6 semanas por analista) · Mantenimiento (ventanas planificadas y fallas por configuración) · Calibración de turnos (rotación, horas, analistas por franja y fallas) · Diccionario (51 campos del registro: tipo, unidad, valores, cuándo se conoce, papel en el O2, regla que los verifica e indicadores que alimentan) · Indicadores (los 22 indicadores del sistema de variables: cálculo, campos y criterio) · Correlaciones (correlación objetivo entre las tareas de un ensayo y de dónde sale cada una) · Supuestos (lo que no está en las fuentes y deben decidir) · Contraste estructural (para el bloque del 1 de noviembre) · Fuentes (APA 7).
A6: Catálogo | B6: Las decisiones son las celdas amarillas: la complejidad de cada método y las marcas de tipo de muestra (hoja Catálogo), y la regla de complejidad, los multiplicadores de reanálisis y las relaciones de corrida (hoja Calibración del catálogo). Si cambian una complejidad, la participación de los métodos se recalcula para conservar los promedios de Costigliola et al. (2017); revisen la columna «Chequeo» de la calibración. El generador lee la hoja Catálogo con cargar_hoja("Catálogo").
A7: Tipos de muestra | B7: Las decisiones son las celdas amarillas de la hoja Tipos de muestra: la proporción de cada tipo, sus llegadas, su plazo y si puede llegar como urgente. La probabilidad de cada método dentro de cada tipo se recalcula sola (ajuste proporcional iterativo) para conservar la mezcla de técnicas de Costigliola et al. (2017); revisen los chequeos del bloque E de la hoja Calibración de tipos.
A8: Equipos y analistas | B8: Las decisiones son las celdas amarillas: cantidad de equipos y compatibilidad (hoja Equipos), nivel y área de cada analista (hoja Analistas), y configuración principal de cada método, factores de experiencia y áreas (hoja Calibración de recursos). La matriz de calificación se calcula sola: un analista está calificado para un método si su nivel alcanza la calificación mínima del método y si la técnica está en su área. Revisen los chequeos de la hoja Calibración de recursos.
A9: Turnos y mantenimiento | B9: Las decisiones son las celdas amarillas: horario de cada código (hoja Turnos), desfase de rotación y grupo de almuerzo de cada analista (hoja Calibración de turnos), y frecuencia y duración de las ventanas de mantenimiento y verificación (hoja Mantenimiento). La hoja Rotación se calcula sola y se repite cada 42 días (6 semanas).
A10: Registro del dataset | B10: La unidad de análisis (un registro por ejecución de un ensayo sobre una muestra) y los 51 campos del registro están en docs/Diccionario_de_datos.docx, en la hoja Diccionario y en src/generador/registro.py, que verifica cada regla; la hoja Indicadores amarra los campos con el sistema de variables. Sus supuestos son S27 y S28 (hoja Supuestos) y sus datos, el bloque «Estructura del registro» de la hoja Parámetros.
A11: Columna «Tipo» | B11: Dato de la literatura = valor tal como aparece en la fuente. Derivado = cálculo propio a partir de datos de la fuente (la fórmula está en la celda). Supuesto = no aparece en las fuentes revisadas: hay que justificarlo o tratarlo con escenarios.
A12: Colores | B12: Texto azul = valor tomado de la fuente (no editar salvo que encuentren un error). Texto negro = fórmula. Fondo amarillo = supuesto que deben decidir ustedes (son las únicas celdas pensadas para editar).
A13: Páginas | B13: Se cita el número de página de la revista (el que va en APA), no el del PDF. Ejemplo: Costigliola et al. (2017) va de la p. 9014 a la 9019.
A14: Ojo 1 | B14: Costigliola et al. (2017) usa distribuciones triangulares T(mín, moda, máx). El anteproyecto usa BetaPERT con esos mismos tres puntos: declárenlo en la metodología como una adaptación propia.
A15: Ojo 2 | B15: Las cinco fuentes no traen valores para la tasa de reanálisis por OOS, la indisponibilidad de equipos, el porcentaje de urgentes ni los coeficientes de correlación. Están en la hoja Supuestos con una propuesta de escenarios; necesitan fuente o se declaran como supuestos.
... A17: Ojo 4 | B17: Con BetaPERT estándar (λ = 4) las medias quedan por debajo de las de la triangular de la fuente, porque estas distribuciones son asimétricas: en la preparación del análisis, entre 7 % y 22 % según la técnica (hoja Calibración del catálogo, bloque B). Se decide en el bloque de duraciones: usar λ = 1, que conserva la media de la triangular, o declarar la diferencia.
A19: Ejemplo de colores
A20: 70 | B20: ← dato de la fuente (texto azul)
A21: =A20*1.5 -> 105 | B21: ← fórmula (texto negro)
A22: 0.05 | B22: ← supuesto que deben decidir (fondo amarillo)

Sheet Parámetros
A1: Parámetros con fuente y página
A2: Una fila por parámetro. Filtren por Bloque, Tipo o Dimensión con los filtros del encabezado.
A4: ID | B4: Bloque | C4: Parámetro | D4: Valor | E4: Unidad | F4: Tipo | G4: Fuente | H4: Página / ubicación | I4: Uso sugerido en el generador | J4: Dimensión del sistema de variables
A5: P01 | B5: Laboratorio y recursos | C5: Equipos del laboratorio de referencia | D5: 70 | E5: equipos | F5: Dato de la literatura | G5: Costigliola et al. (2017) | H5: p. 9015, §2 | I5: Tamaño de la planta de equipos del escenario base. | J5: Recursos materiales
A6: P02 | B6: Laboratorio y recursos | C6: Tipos de equipo / técnica analítica | D6: 6: HPLC, GC, PSA (tamaño de partícula), titulación Karl Fischer (KF), DSC y XRPD | E6: tipos | F6: Dato de la literatura | G6: Costigliola et al. (2017) | H6: p. 9015, §2 | I6: Catálogo de técnicas del laboratorio de referencia. | J6: Recursos materiales
A7: P03 | B7: Laboratorio y recursos | C7: Analistas | D7: 20 | E7: analistas | F7: Dato de la literatura | G7: Costigliola et al. (2017) | H7: p. 9015, §2 y §2.1 | I7: Tamaño de la plantilla del escenario base. | J7: Recursos humanos
A8: P04 | B8: Laboratorio y recursos | C8: Horario de operación | D8: 24 h, 7 días para control en proceso; estabilidad, desarrollo y validación de lunes a viernes | E8: No aplica | F8: Dato de la literatura | G8: Costigliola et al. (2017) | H8: p. 9015, §2.1 | I8: Calendario de disponibilidad del laboratorio. | J8: Recursos humanos
A9: P05 | B9: Laboratorio y recursos | C9: Turnos (Tabla 1) | D9: Turno 1: 7 días, 8:00–20:00 y 20:00–8:00, 2 analistas por turno · Turno 2: 5 días, 8:00–17:00 y 17:00–24:00, 2 por turno · Turno 3: 5 días, 8:00–17:00, 10 analistas | E9: No aplica | F9: Dato de la literatura | G9: Costigliola et al. (2017) | H9: p. 9015, Tabla 1 | I9: Calendarios de disponibilidad de cada analista. | J9: Recursos humanos
A10: P06 | B10: Laboratorio y recursos | C10: Distribución de la plantilla por turno | D10: 6 analistas en turnos rotativos de 12 h, 4 en dos turnos de 8 h y 10 en turno fijo de 8 h, 5 días a la semana | E10: No aplica | F10: Dato de la literatura | G10: Costigliola et al. (2017) | H10: p. 9015, §2.1 | I10: Asignar turno a cada analista generado. | J10: Recursos humanos
A11: P07 | B11: Laboratorio y recursos | C11: Recursos en instancia diaria realista | D11: 15 máquinas y 5 analistas | E11: No aplica | F11: Dato de la literatura | G11: Cunha et al. (2019) | H11: p. 1425, §4.2 | I11: Escenario reducido (diario) para pruebas rápidas del simulador. | J11: Recursos materiales
A12: P08 | B12: Laboratorio y recursos | C12: Recursos en experimentos de Martins | D12: 7 máquinas (tipos de equipo); 2, 3 o 7 analistas (restringido por analistas, balanceado, restringido por máquinas) | E12: No aplica | F12: Dato de la literatura | G12: Martins et al. (2023) | H12: p. 191, §6.1 | I12: Inspiración para escenarios con distinta relación analistas/equipos. | J12: Recursos humanos
A13: P09 | B13: Estructura de ensayos | C13: Tareas de un análisis (modelo de Costigliola) | D13: Preparación del sistema (soluciones y materiales), montaje del equipo, preparación de la muestra en paralelo con la idoneidad del sistema, análisis y procesamiento de datos | E13: No aplica | F13: Dato de la literatura | G13: Costigliola et al. (2017) | H13: pp. 9015–9016, Fig. 1 | I13: Secuencia de tareas de cada actividad analítica. | J13: Tiempos de ejecución
A14: P10 | B14: Estructura de ensayos | C14: Tareas de un ensayo (modelo de Coito) | D14: Seis tareas en orden: preparación del sistema, idoneidad del sistema, preparación de la muestra, corrida analítica, procesamiento de datos y revisión | E14: No aplica | F14: Dato de la literatura | G14: Coito et al. (2021) | H14: p. 72, §4 | I14: Igual al anterior, más la revisión final. | J14: Tiempos de ejecución
A15: P11 | B15: Estructura de ensayos | C15: Recurso que exige cada tarea | D15: Analista, equipo o ambos; el recurso puede requerirse toda la tarea o solo un porcentaje de ella | E15: No aplica | F15: Dato de la literatura | G15: Coito et al. (2021) | H15: p. 72, §4 | I15: Marcar en cada tarea si ocupa analista, equipo o ambos. | J15: Disponibilidad cruzada de recursos
A16: P12 | B16: Estructura de ensayos | C16: Analista como recurso secundario | D16: El analista es un recurso secundario que solo se requiere en tareas específicas; en la Fig. 3, el equipo queda ocupado desde el inicio de la idoneidad hasta el fin de la corrida | E16: No aplica | F16: Dato de la literatura | G16: Costigliola et al. (2017) | H16: p. 9017, §3.3 | I16: Doble restricción: el equipo se ocupa entero y el analista por tramos. | J16: Disponibilidad cruzada de recursos
A17: P13 | B17: Estructura de ensayos | C17: Unidad de análisis | D17: La pareja muestra/análisis es una entidad y se procesa en un solo equipo | E17: No aplica | F17: Dato de la literatura | G17: Costigliola et al. (2017) | H17: p. 9017, §3.3 (supuesto 1) | I17: Coincide con la unidad de análisis del anteproyecto (§1.4). | J17: Variabilidad y consistencia estructural
A18: P14 | B18: Estructura de ensayos | C18: Ensayos por muestra | D18: 85 % de las muestras con 1 ensayo, ~10 % con 2 y ~5 % con 3 | E18: % de muestras | F18: Dato de la literatura | G18: Cunha et al. (2019) | H18: p. 1425, §4.2 | I18: Número de actividades por muestra (ver hoja Demanda). | J18: Variabilidad y consistencia estructural
A19: P15 | B19: Estructura de ensayos | C19: Tipos de trabajo (Tabla 1) | D19: A: 3 operaciones con precedencia (tiempos 3, 2, 1) · B: 2 operaciones con precedencia (5, 4) · C: 1 operación (1) | E19: unidades de tiempo | F19: Dato de la literatura | G19: Cunha et al. (2019) | H19: p. 1424, Tabla 1 | I19: Plantillas de muestra con precedencias entre ensayos. | J19: Variabilidad y consistencia estructural
... A83: P79 | B83: Estructura del registro | C83: Predecesores de una tarea | D83: Cada tarea puede tener una lista de predecesores directos, solo dentro del mismo proyecto | E83: No aplica | F83: Dato de la literatura | G83: Mischek y Musliu (2021) | H83: p. 539, §3 | I83: No se aplica (S28); en el TLSP la precedencia es opcional. | J83: Variabilidad y consistencia estructural

Sheet Duraciones
A1: Duraciones: tres puntos por técnica y tarea
A2: Costigliola et al. (2017), Tabla 3, p. 9016. Minutos. a = mínimo, m = moda, b = máximo. Media PERT y desviaciones con fórmula: la aproximada de los libros, (b−a)/6, y la exacta de la BetaPERT con λ = 4, que usa src/generador/duraciones.py.
A4: Técnica | B4: Tarea | C4: Distribución original | D4: a (mín) | E4: m (moda) | F4: b (máx) | G4: Media PERT (a+4m+b)/6 | H4: Desv. aproximada (b−a)/6 | I4: Desv. BetaPERT exacta (λ = 4) | J4: Media triangular (a+m+b)/3 | K4: Tipo | L4: Nota
A5: HPLC | B5: Preparación de muestra | C5: T(5, 40, 100) | D5: 5 | E5: 40 | F5: 100 | G5: =IF(COUNT(D5:F5)=3,(D5+4*E5+F5)/6,"") -> 44.166667 | H5: =IF(COUNT(D5:F5)=3,(F5-D5)/6,"") -> 15.833333 | I5: =IF(COUNT(D5:F5)=3,SQRT((G5-D5)*(F5-G5)/7),"") -> 17.674863 | J5: =IF(COUNT(D5:F5)=3,(D5+E5+F5)/3,"") -> 48.333333 | K5: Dato de la literatura
A6: HPLC | B6: Montaje del equipo | C6: T(25, 50, 65) | D6: 25 | E6: 50 | F6: 65 | G6: =IF(COUNT(D6:F6)=3,(D6+4*E6+F6)/6,"") -> 48.333333 | H6: =IF(COUNT(D6:F6)=3,(F6-D6)/6,"") -> 6.6666667 | I6: =IF(COUNT(D6:F6)=3,SQRT((G6-D6)*(F6-G6)/7),"") -> 7.4535599 | J6: =IF(COUNT(D6:F6)=3,(D6+E6+F6)/3,"") -> 46.666667 | K6: Dato de la literatura
A7: HPLC | B7: Corrida | C7: Det. | G7: =IF(COUNT(D7:F7)=3,(D7+4*E7+F7)/6,"") | H7: =IF(COUNT(D7:F7)=3,(F7-D7)/6,"") | I7: =IF(COUNT(D7:F7)=3,SQRT((G7-D7)*(F7-G7)/7),"") | J7: =IF(COUNT(D7:F7)=3,(D7+E7+F7)/3,"") | K7: Dato + supuesto | L7: Determinista en la fuente (sale del informe de cada método, no se publica). La corrida por método está en la hoja Catálogo (supuestos S05 y S14).
A8: HPLC | B8: Procesamiento de datos | C8: T(2, 5, 10) | D8: 2 | E8: 5 | F8: 10 | G8: =IF(COUNT(D8:F8)=3,(D8+4*E8+F8)/6,"") -> 5.3333333 | H8: =IF(COUNT(D8:F8)=3,(F8-D8)/6,"") -> 1.3333333 | I8: =IF(COUNT(D8:F8)=3,SQRT((G8-D8)*(F8-G8)/7),"") -> 1.490712 | J8: =IF(COUNT(D8:F8)=3,(D8+E8+F8)/3,"") -> 5.6666667 | K8: Dato de la literatura
A9: GC | B9: Preparación de muestra | C9: T(5, 10, 35) | D9: 5 | E9: 10 | F9: 35 | G9: =IF(COUNT(D9:F9)=3,(D9+4*E9+F9)/6,"") -> 13.333333 | H9: =IF(COUNT(D9:F9)=3,(F9-D9)/6,"") -> 5 | I9: =IF(COUNT(D9:F9)=3,SQRT((G9-D9)*(F9-G9)/7),"") -> 5.078745 | J9: =IF(COUNT(D9:F9)=3,(D9+E9+F9)/3,"") -> 16.666667 | K9: Dato de la literatura
A10: GC | B10: Montaje del equipo | C10: T(2, 5, 30) | D10: 2 | E10: 5 | F10: 30 | G10: =IF(COUNT(D10:F10)=3,(D10+4*E10+F10)/6,"") -> 8.6666667 | H10: =IF(COUNT(D10:F10)=3,(F10-D10)/6,"") -> 4.6666667 | I10: =IF(COUNT(D10:F10)=3,SQRT((G10-D10)*(F10-G10)/7),"") -> 4.5074894 | J10: =IF(COUNT(D10:F10)=3,(D10+E10+F10)/3,"") -> 12.333333 | K10: Dato de la literatura
A11: GC | B11: Corrida | C11: Det. | G11: =IF(COUNT(D11:F11)=3,(D11+4*E11+F11)/6,"") | H11: =IF(COUNT(D11:F11)=3,(F11-D11)/6,"") | I11: =IF(COUNT(D11:F11)=3,SQRT((G11-D11)*(F11-G11)/7),"") | J11: =IF(COUNT(D11:F11)=3,(D11+E11+F11)/3,"") | K11: Dato + supuesto | L11: Determinista en la fuente (sale del informe de cada método, no se publica). La corrida por método está en la hoja Catálogo (supuestos S05 y S14).
A12: GC | B12: Procesamiento de datos | C12: T(10, 20, 45) | D12: 10 | E12: 20 | F12: 45 | G12: =IF(COUNT(D12:F12)=3,(D12+4*E12+F12)/6,"") -> 22.5 | H12: =IF(COUNT(D12:F12)=3,(F12-D12)/6,"") -> 5.8333333 | I12: =IF(COUNT(D12:F12)=3,SQRT((G12-D12)*(F12-G12)/7),"") -> 6.3386569 | J12: =IF(COUNT(D12:F12)=3,(D12+E12+F12)/3,"") -> 25 | K12: Dato de la literatura
A13: PSA | B13: Preparación de muestra | C13: T(5, 7.5, 21) | D13: 5 | E13: 7.5 | F13: 21 | G13: =IF(COUNT(D13:F13)=3,(D13+4*E13+F13)/6,"") -> 9.3333333 | H13: =IF(COUNT(D13:F13)=3,(F13-D13)/6,"") -> 2.6666667 | I13: =IF(COUNT(D13:F13)=3,SQRT((G13-D13)*(F13-G13)/7),"") -> 2.6874192 | J13: =IF(COUNT(D13:F13)=3,(D13+E13+F13)/3,"") -> 11.166667 | K13: Dato de la literatura
A14: PSA | B14: Montaje del equipo | C14: U(1, 32) | D14: 1 | E14: =(D14+F14)/2 -> 16.5 | F14: 32 | G14: =IF(COUNT(D14:F14)=3,(D14+4*E14+F14)/6,"") -> 16.5 | H14: =IF(COUNT(D14:F14)=3,(F14-D14)/6,"") -> 5.1666667 | I14: =IF(COUNT(D14:F14)=3,SQRT((G14-D14)*(F14-G14)/7),"") -> 5.8584493 | J14: =IF(COUNT(D14:F14)=3,(D14+E14+F14)/3,"") -> 16.5 | K14: Dato + supuesto | L14: La fuente da una uniforme U(mín, máx). Para BetaPERT se propone la moda en el punto medio (supuesto); también pueden dejarla uniforme.
A15: PSA | B15: Corrida | C15: T(5, 10, 30) | D15: 5 | E15: 10 | F15: 30 | G15: =IF(COUNT(D15:F15)=3,(D15+4*E15+F15)/6,"") -> 12.5 | H15: =IF(COUNT(D15:F15)=3,(F15-D15)/6,"") -> 4.1666667 | I15: =IF(COUNT(D15:F15)=3,SQRT((G15-D15)*(F15-G15)/7),"") -> 4.330127 | J15: =IF(COUNT(D15:F15)=3,(D15+E15+F15)/3,"") -> 15 | K15: Dato de la literatura
A16: PSA | B16: Procesamiento de datos | C16: T(2, 6, 10) | D16: 2 | E16: 6 | F16: 10 | G16: =IF(COUNT(D16:F16)=3,(D16+4*E16+F16)/6,"") -> 6 | H16: =IF(COUNT(D16:F16)=3,(F16-D16)/6,"") -> 1.3333333 | I16: =IF(COUNT(D16:F16)=3,SQRT((G16-D16)*(F16-G16)/7),"") -> 1.5118579 | J16: =IF(COUNT(D16:F16)=3,(D16+E16+F16)/3,"") -> 6 | K16: Dato de la literatura
A17: KF | B17: Preparación de muestra | C17: T(1, 6, 25) | D17: 1 | E17: 6 | F17: 25 | G17: =IF(COUNT(D17:F17)=3,(D17+4*E17+F17)/6,"") -> 8.3333333 | H17: =IF(COUNT(D17:F17)=3,(F17-D17)/6,"") -> 4 | I17: =IF(COUNT(D17:F17)=3,SQRT((G17-D17)*(F17-G17)/7),"") -> 4.1785545 | J17: =IF(COUNT(D17:F17)=3,(D17+E17+F17)/3,"") -> 10.666667 | K17: Dato de la literatura
A18: KF | B18: Montaje del equipo | C18: T(4, 8, 16) | D18: 4 | E18: 8 | F18: 16 | G18: =IF(COUNT(D18:F18)=3,(D18+4*E18+F18)/6,"") -> 8.6666667 | H18: =IF(COUNT(D18:F18)=3,(F18-D18)/6,"") -> 2 | I18: =IF(COUNT(D18:F18)=3,SQRT((G18-D18)*(F18-G18)/7),"") -> 2.2110832 | J18: =IF(COUNT(D18:F18)=3,(D18+E18+F18)/3,"") -> 9.3333333 | K18: Dato de la literatura
A19: KF | B19: Corrida | C19: T(2, 5, 56) | D19: 2 | E19: 5 | F19: 56 | G19: =IF(COUNT(D19:F19)=3,(D19+4*E19+F19)/6,"") -> 13 | H19: =IF(COUNT(D19:F19)=3,(F19-D19)/6,"") -> 9 | I19: =IF(COUNT(D19:F19)=3,SQRT((G19-D19)*(F19-G19)/7),"") -> 8.2201842 | J19: =IF(COUNT(D19:F19)=3,(D19+E19+F19)/3,"") -> 21 | K19: Dato de la literatura
A20: KF | B20: Procesamiento de datos | C20: T(10, 20, 30) | D20: 10 | E20: 20 | F20: 30 | G20: =IF(COUNT(D20:F20)=3,(D20+4*E20+F20)/6,"") -> 20 | H20: =IF(COUNT(D20:F20)=3,(F20-D20)/6,"") -> 3.3333333 | I20: =IF(COUNT(D20:F20)=3,SQRT((G20-D20)*(F20-G20)/7),"") -> 3.7796447 | J20: =IF(COUNT(D20:F20)=3,(D20+E20+F20)/3,"") -> 20 | K20: Dato de la literatura
A21: DSC | B21: Preparación de muestra | C21: T(5, 10, 30) | D21: 5 | E21: 10 | F21: 30 | G21: =IF(COUNT(D21:F21)=3,(D21+4*E21+F21)/6,"") -> 12.5 | H21: =IF(COUNT(D21:F21)=3,(F21-D21)/6,"") -> 4.1666667 | I21: =IF(COUNT(D21:F21)=3,SQRT((G21-D21)*(F21-G21)/7),"") -> 4.330127 | J21: =IF(COUNT(D21:F21)=3,(D21+E21+F21)/3,"") -> 15 | K21: Dato de la literatura
A22: DSC | B22: Montaje del equipo | C22: T(1, 3, 12) | D22: 1 | E22: 3 | F22: 12 | G22: =IF(COUNT(D22:F22)=3,(D22+4*E22+F22)/6,"") -> 4.1666667 | H22: =IF(COUNT(D22:F22)=3,(F22-D22)/6,"") -> 1.8333333 | I22: =IF(COUNT(D22:F22)=3,SQRT((G22-D22)*(F22-G22)/7),"") -> 1.8824587 | J22: =IF(COUNT(D22:F22)=3,(D22+E22+F22)/3,"") -> 5.3333333 | K22: Dato de la literatura
A23: DSC | B23: Corrida | C23: U(12, 180) | D23: 12 | E23: =(D23+F23)/2 -> 96 | F23: 180 | G23: =IF(COUNT(D23:F23)=3,(D23+4*E23+F23)/6,"") -> 96 | H23: =IF(COUNT(D23:F23)=3,(F23-D23)/6,"") -> 28 | I23: =IF(COUNT(D23:F23)=3,SQRT((G23-D23)*(F23-G23)/7),"") -> 31.749016 | J23: =IF(COUNT(D23:F23)=3,(D23+E23+F23)/3,"") -> 96 | K23: Dato + supuesto | L23: La fuente da una uniforme U(mín, máx). Para BetaPERT se propone la moda en el punto medio (supuesto); también pueden dejarla uniforme.
A24: DSC | B24: Procesamiento de datos | C24: T(4, 9, 16) | D24: 4 | E24: 9 | F24: 16 | G24: =IF(COUNT(D24:F24)=3,(D24+4*E24+F24)/6,"") -> 9.3333333 | H24: =IF(COUNT(D24:F24)=3,(F24-D24)/6,"") -> 2 | I24: =IF(COUNT(D24:F24)=3,SQRT((G24-D24)*(F24-G24)/7),"") -> 2.2537447 | J24: =IF(COUNT(D24:F24)=3,(D24+E24+F24)/3,"") -> 9.6666667 | K24: Dato de la literatura
A25: XRPD | B25: Preparación de muestra | C25: T(5, 10, 20) | D25: 5 | E25: 10 | F25: 20 | G25: =IF(COUNT(D25:F25)=3,(D25+4*E25+F25)/6,"") -> 10.833333 | H25: =IF(COUNT(D25:F25)=3,(F25-D25)/6,"") -> 2.5 | I25: =IF(COUNT(D25:F25)=3,SQRT((G25-D25)*(F25-G25)/7),"") -> 2.763854 | J25: =IF(COUNT(D25:F25)=3,(D25+E25+F25)/3,"") -> 11.666667 | K25: Dato de la literatura
A26: XRPD | B26: Montaje del equipo | C26: T(1, 5, 20) | D26: 1 | E26: 5 | F26: 20 | G26: =IF(COUNT(D26:F26)=3,(D26+4*E26+F26)/6,"") -> 6.8333333 | H26: =IF(COUNT(D26:F26)=3,(F26-D26)/6,"") -> 3.1666667 | I26: =IF(COUNT(D26:F26)=3,SQRT((G26-D26)*(F26-G26)/7),"") -> 3.3124345 | J26: =IF(COUNT(D26:F26)=3,(D26+E26+F26)/3,"") -> 8.6666667 | K26: Dato de la literatura
A27: XRPD | B27: Corrida | C27: T(11, 25, 203) | D27: 11 | E27: 25 | F27: 203 | G27: =IF(COUNT(D27:F27)=3,(D27+4*E27+F27)/6,"") -> 52.333333 | H27: =IF(COUNT(D27:F27)=3,(F27-D27)/6,"") -> 32 | I27: =IF(COUNT(D27:F27)=3,SQRT((G27-D27)*(F27-G27)/7),"") -> 29.827014 | J27: =IF(COUNT(D27:F27)=3,(D27+E27+F27)/3,"") -> 79.666667 | K27: Dato de la literatura
A28: XRPD | B28: Procesamiento de datos | C28: T(2, 7, 30) | D28: 2 | E28: 7 | F28: 30 | G28: =IF(COUNT(D28:F28)=3,(D28+4*E28+F28)/6,"") -> 10 | H28: =IF(COUNT(D28:F28)=3,(F28-D28)/6,"") -> 4.6666667 | I28: =IF(COUNT(D28:F28)=3,SQRT((G28-D28)*(F28-G28)/7),"") -> 4.7809144 | J28: =IF(COUNT(D28:F28)=3,(D28+E28+F28)/3,"") -> 13 | K28: Dato de la literatura
A29: Fuente: Costigliola et al. (2017), Tabla 3, p. 9016. La conversión de triangular a BetaPERT con los mismos tres puntos es una adaptación propia (declararla en la metodología).
A31: Tiempos promedio por tarea del modelo de Costigliola et al. (2017, Tabla 6, p. 9019) · min · promedio ± desviación (la fuente no explica el ± de esta tabla; en la Tabla 5 es entre corridas, p. 9018)
A32: Técnica | B32: Prep. del sistema | C32: Idoneidad del sistema | D32: Prep. del análisis | E32: Análisis | F32: Proc. de datos
A33: HPLC | B33: 207 ± 14 | C33: 227 ± 11 | D33: 96 ± 3 | E33: 85 ± 1 | F33: 59 ± 2
A34: GC | B34: 67 ± 5 | C34: 152 ± 5 | D34: 48 ± 1 | E34: 62 ± 1 | F34: 39 ± 1
A35: PSA | B35: n.a. | C35: n.a. | D35: 31 ± 1 | E35: 32 ± 1 | F35: 16 ± 1
A36: KF | B36: n.a. | C36: n.a. | D36: 45 ± 3 | E36: 30 ± 2 | F36: 29 ± 2
A37: DSC | B37: n.a. | C37: n.a. | D37: 47 ± 2 | E37: 101 ± 3 | F37: 24 ± 2
A38: XRPD | B38: n.a. | C38: n.a. | D38: 46 ± 1 | E38: 88 ± 3 | F38: 30 ± 1
A39: Uso: referencia de validación para la preparación del análisis y la corrida de HPLC y GC. El procesamiento de datos y la corrida de PSA y KF de esta tabla superan la media (y a veces el máximo) de la Tabla 3, y la fuente no explica por qué. Prep. del sistema/análisis = prep. de muestra × n.º de soluciones (p. 9019).
A41: Tiempos promedio por tarea: estimación de expertos vs. medición (Coito et al., 2021, Tabla 2, p. 74) · min
A42: Tarea | B42: Expertos (sistema anterior) | C42: Medido (sistema propuesto) | D42: Diferencia (fórmula) | E42: Reducción (fórmula) | F42: Reducción reportada
A43: Preparación del sistema | B43: 139 | C43: 93 | D43: =B43-C43 -> 46 | E43: =IF(B43=0,"",D43/B43) -> 0.33093525 | F43: 0.33
...

Sheet Demanda
A1: Demanda: mezcla, volumen y escenarios de carga
A2: Datos de Costigliola et al. (2017) y Cunha et al. (2019). Las celdas amarillas son supuestos que pueden cambiar.
A4: Técnica | B4: % de análisis (Tabla 2) | C4: Análisis requeridos al año (Tabla 4) | D4: % según Tabla 4 (fórmula) | E4: Promedio por día calendario (fórmula) | F4: Promedio por día hábil (fórmula)
A5: HPLC | B5: 0.407 | C5: 6099 | D5: =C5/$C$11 -> 0.39802911 | E5: =C5/$B$14 -> 16.709589 | F5: =C5/$B$15 -> 23.457692
A6: GC | B6: 0.257 | C6: 3910 | D6: =C6/$C$11 -> 0.25517196 | E6: =C6/$B$14 -> 10.712329 | F6: =C6/$B$15 -> 15.038462
A7: PSA | B7: 0.188 | C7: 3014 | D7: =C7/$C$11 -> 0.19669777 | E7: =C7/$B$14 -> 8.2575342 | F7: =C7/$B$15 -> 11.592308
A8: KF | B8: 0.071 | C8: 1240 | D8: =C8/$C$11 -> 0.080924101 | E8: =C8/$B$14 -> 3.3972603 | F8: =C8/$B$15 -> 4.7692308
A9: DSC | B9: 0.04 | C9: 581 | D9: =C9/$C$11 -> 0.037916857 | E9: =C9/$B$14 -> 1.5917808 | F9: =C9/$B$15 -> 2.2346154
A10: XRPD | B10: 0.037 | C10: 479 | D10: =C10/$C$11 -> 0.031260197 | E10: =C10/$B$14 -> 1.3123288 | F10: =C10/$B$15 -> 1.8423077
A11: Total | B11: =SUM(B5:B10) -> 1 | C11: =SUM(C5:C10) -> 15323 | D11: =SUM(D5:D10) -> 1 | E11: =SUM(E5:E10) -> 41.980822 | F11: =SUM(F5:F10) -> 58.934615
A12: Fuente: Costigliola et al. (2017), Tabla 2 (p. 9016) y Tabla 4 (p. 9018, año 2015). Las dos tablas no coinciden exactamente (hasta 1 punto porcentual) y la fuente no explica por qué: la Tabla 2 sale de la tabla de llegadas del LIMS (p. 9016) y la Tabla 4, de la validación con el año 2015 (p. 9018); elijan una y declárenlo.
A14: Días calendario al año | B14: 365 | C14: El control en proceso funciona 24/7 (Costigliola et al., 2017, p. 9015).
A15: Días hábiles al año | B15: 260 | C15: Supuesto: 52 semanas × 5 días (estabilidad, desarrollo y validación van de lunes a viernes, p. 9015).
A17: Ensayos por muestra (Cunha et al., 2019, p. 1425)
A18: N.º de ensayos | B18: % de muestras | C18: Aporte (fórmula)
A19: 1 | B19: 0.85 | C19: =A19*B19 -> 0.85
A20: 2 | B20: 0.1 | C20: =A20*B20 -> 0.2
A21: 3 | B21: 0.05 | C21: =A21*B21 -> 0.15
A22: Ensayos promedio por muestra | C22: =SUM(C19:C21) -> 1.2
A23: Chequeo: los % suman | C23: =SUM(B19:B21) -> 1
A25: Escenarios de carga (análisis por día calendario)
A26: Escenario | B26: Multiplicador | C26: Análisis por día (fórmula) | D26: Muestras por día (fórmula) | E26: Origen
A27: Baja | B27: 0.7 | C27: =$E$11*B27 -> 29.386575 | D27: =IF($C$22=0,"",C27/$C$22) -> 24.488813 | E27: Supuesto: −30 % respecto a la base (pueden cambiarlo).
A28: Base | B28: 1 | C28: =$E$11*B28 -> 41.980822 | D28: =IF($C$22=0,"",C28/$C$22) -> 34.984018 | E28: Volumen 2015 de Costigliola et al. (2017), Tabla 4.
A29: Alta | B29: 1.5 | C29: =$E$11*B29 -> 62.971233 | D29: =IF($C$22=0,"",C29/$C$22) -> 52.476027 | E29: +50 %, escenario 2 de Costigliola et al. (2017), p. 9019.
A31: Chequeo con Cunha et al. (2019, pp. 1424–1425): una carga diaria realista tiene 30–40 trabajos y 35–52 operaciones; comparen con la fila Base.

Sheet Catálogo
A1: Catálogo de métodos del laboratorio de referencia
A2: Doce ensayos típicos, dos por técnica. Amarillo = decisión (complejidad y tipos de muestra); el resto se calcula en la hoja Calibración del catálogo.
A3: Fuentes: técnicas y mezcla de Costigliola et al. (2017, pp. 9015–9016); ensayos de ICH Q6A (1999, §3.2.1 y §3.3.1); capítulos generales de la USP–NF. Tipos de muestra: MP materia prima, IN intermedio, GR granel, PT producto terminado, ES estabilidad.
A4: ID | B4: Técnica | C4: Ensayo | D4: Qué mide | E4: Referencia | F4: Equipo requerido | G4: Requiere idoneidad | H4: Complejidad | I4: Soluciones mín | J4: Soluciones máx | K4: Calificación mínima | L4: Participación en la técnica | M4: Participación en la demanda | N4: Corrida: regla | O4: Corrida mín (min) | P4: Corrida moda (min) | Q4: Corrida máx (min) | R4: Cuantil desde | S4: Cuantil hasta | T4: Corrida promedio (min) | U4: Prob. de reanálisis | V4: MP | W4: IN | X4: GR | Y4: PT | Z4: ES | AA4: Por qué esa complejidad
A5: M01 | B5: HPLC | C5: Valoración del principio activo | D5: Contenido del principio activo frente a un estándar de referencia; la identificación por tiempo de retención sale de la misma corrida | E5: USP <621> | F5: HPLC con detector UV | G5: Sí | H5: baja | I5: =INDEX('Calibración del catálogo'!$B$6:$B$8,MATCH(H5,'Calibración del catálogo'!$A$6:$A$8,0)) -> 1 | J5: =INDEX('Calibración del catálogo'!$C$6:$C$8,MATCH(H5,'Calibración del catálogo'!$A$6:$A$8,0)) -> 2 | K5: =INDEX('Calibración del catálogo'!$E$6:$E$8,MATCH(H5,'Calibración del catálogo'!$A$6:$A$8,0)) -> Júnior o superior | L5: =IFERROR(INDEX('Calibración del catálogo'!$L$16:$L$21,MATCH(A5,'Calibración del catálogo'!$H$16:$H$21,0)),INDEX('Calibración del catálogo'!$M$16:$M$21,MATCH(A5,'Calibración del catálogo'!$J$16:$J$21,0))) -> 0.75689655 | M5: =IFERROR(L5*INDEX(Demanda!$B$5:$B$10,MATCH(B5,Demanda!$A$5:$A$10,0)),"revisar") -> 0.3080569 | N5: Triangular alrededor de la moda (S05 y S14) | O5: =IFERROR(P5*(1-'Calibración del catálogo'!$D$25),"revisar") -> 49.829438 | P5: ='Calibración del catálogo'!E25 -> 62.286797 | Q5: =IFERROR(P5*(1+'Calibración del catálogo'!$D$25),"revisar") -> 74.744157 | T5: =P5 -> 62.286797 | U5: =INDEX('Calibración del catálogo'!$H$6:$H$8,MATCH(H5,'Calibración del catálogo'!$A$6:$A$8,0)) -> 0.012466403 | V5: X | W5: X | X5: X | Y5: X | Z5: X | AA5: Muestra por duplicado; los estándares van en la preparación del sistema.
A6: M02 | B6: HPLC | C6: Sustancias relacionadas | D6: Impurezas orgánicas y productos de degradación | E6: USP <621> y <1086> | F6: HPLC con detector UV/DAD y gradiente | G6: Sí | H6: media | I6: =INDEX('Calibración del catálogo'!$B$6:$B$8,MATCH(H6,'Calibración del catálogo'!$A$6:$A$8,0)) -> 3 | J6: =INDEX('Calibración del catálogo'!$C$6:$C$8,MATCH(H6,'Calibración del catálogo'!$A$6:$A$8,0)) -> 4 | K6: =INDEX('Calibración del catálogo'!$E$6:$E$8,MATCH(H6,'Calibración del catálogo'!$A$6:$A$8,0)) -> Intermedio o superior | L6: =IFERROR(INDEX('Calibración del catálogo'!$L$16:$L$21,MATCH(A6,'Calibración del catálogo'!$H$16:$H$21,0)),INDEX('Calibración del catálogo'!$M$16:$M$21,MATCH(A6,'Calibración del catálogo'!$J$16:$J$21,0))) -> 0.24310345 | M6: =IFERROR(L6*INDEX(Demanda!$B$5:$B$10,MATCH(B6,Demanda!$A$5:$A$10,0)),"revisar") -> 0.098943103 | N6: Triangular alrededor de la moda (S05 y S14) | O6: =IFERROR(P6*(1-'Calibración del catálogo'!$D$25),"revisar") -> 124.57359 | P6: ='Calibración del catálogo'!F25 -> 155.71699 | Q6: =IFERROR(P6*(1+'Calibración del catálogo'!$D$25),"revisar") -> 186.86039 | T6: =P6 -> 155.71699 | U6: =INDEX('Calibración del catálogo'!$H$6:$H$8,MATCH(H6,'Calibración del catálogo'!$A$6:$A$8,0)) -> 0.024932807 | V6: X | X6: X | Y6: X | Z6: X | AA6: Muestra por duplicado, muestra adicionada y estándar diluido.
A7: M03 | B7: GC | C7: Pureza de materias primas volátiles | D7: Pureza de solventes y otras materias primas volátiles | E7: USP <621> | F7: GC con inyección líquida y detector FID | G7: Sí | H7: baja | I7: =INDEX('Calibración del catálogo'!$B$6:$B$8,MATCH(H7,'Calibración del catálogo'!$A$6:$A$8,0)) -> 1 | J7: =INDEX('Calibración del catálogo'!$C$6:$C$8,MATCH(H7,'Calibración del catálogo'!$A$6:$A$8,0)) -> 2 | K7: =INDEX('Calibración del catálogo'!$E$6:$E$8,MATCH(H7,'Calibración del catálogo'!$A$6:$A$8,0)) -> Júnior o superior | L7: =IFERROR(INDEX('Calibración del catálogo'!$L$16:$L$21,MATCH(A7,'Calibración del catálogo'!$H$16:$H$21,0)),INDEX('Calibración del catálogo'!$M$16:$M$21,MATCH(A7,'Calibración del catálogo'!$J$16:$J$21,0))) -> 0.31 | M7: =IFERROR(L7*INDEX(Demanda!$B$5:$B$10,MATCH(B7,Demanda!$A$5:$A$10,0)),"revisar") -> 0.07967 | N7: Triangular alrededor de la moda (S05 y S14) | O7: =IFERROR(P7*(1-'Calibración del catálogo'!$D$26),"revisar") -> 36.877323 | P7: ='Calibración del catálogo'!E26 -> 46.096654 | Q7: =IFERROR(P7*(1+'Calibración del catálogo'!$D$26),"revisar") -> 55.315985 | T7: =P7 -> 46.096654 | U7: =INDEX('Calibración del catálogo'!$H$6:$H$8,MATCH(H7,'Calibración del catálogo'!$A$6:$A$8,0)) -> 0.012466403 | V7: X | AA7: Una o dos inyecciones directas del líquido.
A8: M04 | B8: GC | C8: Solventes residuales | D8: Solventes orgánicos que quedan del proceso de fabricación | E8: USP <467> | F8: GC con muestreador de espacio de cabeza y detector FID | G8: Sí | H8: media | I8: =INDEX('Calibración del catálogo'!$B$6:$B$8,MATCH(H8,'Calibración del catálogo'!$A$6:$A$8,0)) -> 3 | J8: =INDEX('Calibración del catálogo'!$C$6:$C$8,MATCH(H8,'Calibración del catálogo'!$A$6:$A$8,0)) -> 4 | K8: =INDEX('Calibración del catálogo'!$E$6:$E$8,MATCH(H8,'Calibración del catálogo'!$A$6:$A$8,0)) -> Intermedio o superior | L8: =IFERROR(INDEX('Calibración del catálogo'!$L$16:$L$21,MATCH(A8,'Calibración del catálogo'!$H$16:$H$21,0)),INDEX('Calibración del catálogo'!$M$16:$M$21,MATCH(A8,'Calibración del catálogo'!$J$16:$J$21,0))) -> 0.69 | M8: =IFERROR(L8*INDEX(Demanda!$B$5:$B$10,MATCH(B8,Demanda!$A$5:$A$10,0)),"revisar") -> 0.17733 | N8: Triangular alrededor de la moda (S05 y S14) | O8: =IFERROR(P8*(1-'Calibración del catálogo'!$D$26),"revisar") -> 55.315985 | P8: ='Calibración del catálogo'!F26 -> 69.144981 | Q8: =IFERROR(P8*(1+'Calibración del catálogo'!$D$26),"revisar") -> 82.973978 | T8: =P8 -> 69.144981 | U8: =INDEX('Calibración del catálogo'!$H$6:$H$8,MATCH(H8,'Calibración del catálogo'!$A$6:$A$8,0)) -> 0.024932807 | V8: X | W8: X | X8: X | Y8: X | AA8: Viales de muestra por duplicado y muestra adicionada.
A9: M05 | B9: PSA | C9: Tamaño de partícula, vía seca | D9: Distribución de tamaño por difracción láser, con la muestra dispersa en aire | E9: USP <429> | F9: Analizador de difracción láser con módulo seco | G9: No | H9: baja | I9: =INDEX('Calibración del catálogo'!$B$6:$B$8,MATCH(H9,'Calibración del catálogo'!$A$6:$A$8,0)) -> 1 | J9: =INDEX('Calibración del catálogo'!$C$6:$C$8,MATCH(H9,'Calibración del catálogo'!$A$6:$A$8,0)) -> 2 | K9: =INDEX('Calibración del catálogo'!$E$6:$E$8,MATCH(H9,'Calibración del catálogo'!$A$6:$A$8,0)) -> Júnior o superior | L9: =IFERROR(INDEX('Calibración del catálogo'!$L$16:$L$21,MATCH(A9,'Calibración del catálogo'!$H$16:$H$21,0)),INDEX('Calibración del catálogo'!$M$16:$M$21,MATCH(A9,'Calibración del catálogo'!$J$16:$J$21,0))) -> 0.3619403 | M9: =IFERROR(L9*INDEX(Demanda!$B$5:$B$10,MATCH(B9,Demanda!$A$5:$A$10,0)),"revisar") -> 0.068044776 | N9: Tramo inferior de la distribución de la Tabla 3 (S15) | O9: ='Calibración del catálogo'!C30 -> 5 | Q9: ='Calibración del catálogo'!G30 -> 12.138593 | R9: 0 | S9: ='Calibración del catálogo'!F30 -> 0.3619403 | T9: ='Calibración del catálogo'!H30 -> 9.5484574 | U9: =INDEX('Calibración del catálogo'!$H$6:$H$8,MATCH(H9,'Calibración del catálogo'!$A$6:$A$8,0)) -> 0.012466403 | V9: X | W9: X | X9: X | AA9: Una o dos alícuotas en seco.
A10: M06 | B10: PSA | C10: Tamaño de partícula, vía húmeda | D10: La misma distribución, con la muestra dispersa en un líquido | E10: USP <429> | F10: Analizador de difracción láser con módulo húmedo | G10: No | H10: media | I10: =INDEX('Calibración del catálogo'!$B$6:$B$8,MATCH(H10,'Calibración del catálogo'!$A$6:$A$8,0)) -> 3 | J10: =INDEX('Calibración del catálogo'!$C$6:$C$8,MATCH(H10,'Calibración del catálogo'!$A$6:$A$8,0)) -> 4 | K10: =INDEX('Calibración del catálogo'!$E$6:$E$8,MATCH(H10,'Calibración del catálogo'!$A$6:$A$8,0)) -> Intermedio o superior | L10: =IFERROR(INDEX('Calibración del catálogo'!$L$16:$L$21,MATCH(A10,'Calibración del catálogo'!$H$16:$H$21,0)),INDEX('Calibración del catálogo'!$M$16:$M$21,MATCH(A10,'Calibración del catálogo'!$J$16:$J$21,0))) -> 0.6380597 | M10: =IFERROR(L10*INDEX(Demanda!$B$5:$B$10,MATCH(B10,Demanda!$A$5:$A$10,0)),"revisar") -> 0.11995522 | N10: Tramo superior de la distribución de la Tabla 3 (S15) | O10: ='Calibración del catálogo'!G30 -> 12.138593 | Q10: ='Calibración del catálogo'!E30 -> 30 | R10: ='Calibración del catálogo'!F30 -> 0.3619403 | S10: 1 | T10: ='Calibración del catálogo'!I30 -> 18.092396 | U10: =INDEX('Calibración del catálogo'!$H$6:$H$8,MATCH(H10,'Calibración del catálogo'!$A$6:$A$8,0)) -> 0.024932807 | V10: X | X10: X | Y10: X | Z10: X | AA10: Dispersante, suspensión de la muestra y réplicas de medición.
A11: M07 | B11: KF | C11: Agua por KF volumétrico | D11: Contenido de agua por titulación directa | E11: USP <921>, método Ia | F11: Titulador Karl Fischer volumétrico | G11: No | H11: media | I11: =INDEX('Calibración del catálogo'!$B$6:$B$8,MATCH(H11,'Calibración del catálogo'!$A$6:$A$8,0)) -> 3 | J11: =INDEX('Calibración del catálogo'!$C$6:$C$8,MATCH(H11,'Calibración del catálogo'!$A$6:$A$8,0)) -> 4 | K11: =INDEX('Calibración del catálogo'!$E$6:$E$8,MATCH(H11,'Calibración del catálogo'!$A$6:$A$8,0)) -> Intermedio o superior | L11: =IFERROR(INDEX('Calibración del catálogo'!$L$16:$L$21,MATCH(A11,'Calibración del catálogo'!$H$16:$H$21,0)),INDEX('Calibración del catálogo'!$M$16:$M$21,MATCH(A11,'Calibración del catálogo'!$J$16:$J$21,0))) -> 0.640625 | M11: =IFERROR(L11*INDEX(Demanda!$B$5:$B$10,MATCH(B11,Demanda!$A$5:$A$10,0)),"revisar") -> 0.045484375 | N11: Tramo inferior de la distribución de la Tabla 3 (S15) | O11: ='Calibración del catálogo'!C31 -> 2 | Q11: ='Calibración del catálogo'!G31 -> 24.540204 | R11: 0 | S11: ='Calibración del catálogo'!F31 -> 0.640625 | T11: ='Calibración del catálogo'!H31 -> 13.131306 | U11: =INDEX('Calibración del catálogo'!$H$6:$H$8,MATCH(H11,'Calibración del catálogo'!$A$6:$A$8,0)) -> 0.024932807 | V11: X | W11: X | X11: X | Y11: X | Z11: X | AA11: Verificación del título y muestra por triplicado.
A12: M08 | B12: KF | C12: Agua por KF coulométrico con horno | D12: Agua en cantidades bajas, liberada en un horno y titulada por coulometría | E12: USP <921>, método Ic | F12: Titulador Karl Fischer coulométrico con horno | G12: No | H12: alta | I12: =INDEX('Calibración del catálogo'!$B$6:$B$8,MATCH(H12,'Calibración del catálogo'!$A$6:$A$8,0)) -> 5 | J12: =INDEX('Calibración del catálogo'!$C$6:$C$8,MATCH(H12,'Calibración del catálogo'!$A$6:$A$8,0)) -> 6 | K12: =INDEX('Calibración del catálogo'!$E$6:$E$8,MATCH(H12,'Calibración del catálogo'!$A$6:$A$8,0)) -> Solo sénior | L12: =IFERROR(INDEX('Calibración del catálogo'!$L$16:$L$21,MATCH(A12,'Calibración del catálogo'!$H$16:$H$21,0)),INDEX('Calibración del catálogo'!$M$16:$M$21,MATCH(A12,'Calibración del catálogo'!$J$16:$J$21,0))) -> 0.359375 | M12: =IFERROR(L12*INDEX(Demanda!$B$5:$B$10,MATCH(B12,Demanda!$A$5:$A$10,0)),"revisar") -> 0.025515625 | N12: Tramo superior de la distribución de la Tabla 3 (S15) | O12: ='Calibración del catálogo'!G31 -> 24.540204 | Q12: ='Calibración del catálogo'!E31 -> 56 | R12: ='Calibración del catálogo'!F31 -> 0.640625 | S12: 1 | T12: ='Calibración del catálogo'!I31 -> 35.026803 | U12: =INDEX('Calibración del catálogo'!$H$6:$H$8,MATCH(H12,'Calibración del catálogo'!$A$6:$A$8,0)) -> 0.049865613 | V12: X | Y12: X | Z12: X | AA12: Viales blanco, estándar de agua y muestra por triplicado.
A13: M09 | B13: DSC | C13: Punto de fusión | D13: Temperatura de fusión, para identificar el material | E13: USP <891> | F13: Calorímetro diferencial de barrido | G13: No | H13: baja | I13: =INDEX('Calibración del catálogo'!$B$6:$B$8,MATCH(H13,'Calibración del catálogo'!$A$6:$A$8,0)) -> 1 | J13: =INDEX('Calibración del catálogo'!$C$6:$C$8,MATCH(H13,'Calibración del catálogo'!$A$6:$A$8,0)) -> 2 | K13: =INDEX('Calibración del catálogo'!$E$6:$E$8,MATCH(H13,'Calibración del catálogo'!$A$6:$A$8,0)) -> Júnior o superior | L13: =IFERROR(INDEX('Calibración del catálogo'!$L$16:$L$21,MATCH(A13,'Calibración del catálogo'!$H$16:$H$21,0)),INDEX('Calibración del catálogo'!$M$16:$M$21,MATCH(A13,'Calibración del catálogo'!$J$16:$J$21,0))) -> 0.18333333 | M13: =IFERROR(L13*INDEX(Demanda!$B$5:$B$10,MATCH(B13,Demanda!$A$5:$A$10,0)),"revisar") -> 0.0073333333 | N13: Tramo inferior de la distribución de la Tabla 3 (S15) | O13: ='Calibración del catálogo'!C32 -> 12 | Q13: ='Calibración del catálogo'!G32 -> 42.8 | R13: 0 | S13: ='Calibración del catálogo'!F32 -> 0.18333333 | T13: ='Calibración del catálogo'!H32 -> 27.4 | U13: =INDEX('Calibración del catálogo'!$H$6:$H$8,MATCH(H13,'Calibración del catálogo'!$A$6:$A$8,0)) -> 0.012466403 | V13: X | W13: X | AA13: Una o dos cápsulas de muestra.
A14: M10 | B14: DSC | C14: Forma polimórfica y pureza | D14: Forma cristalina y pureza a partir del pico de fusión | E14: USP <891> | F14: Calorímetro diferencial de barrido | G14: No | H14: media | I14: =INDEX('Calibración del catálogo'!$B$6:$B$8,MATCH(H14,'Calibración del catálogo'!$A$6:$A$8,0)) -> 3 | J14: =INDEX('Calibración del catálogo'!$C$6:$C$8,MATCH(H14,'Calibración del catálogo'!$A$6:$A$8,0)) -> 4 | K14: =INDEX('Calibración del catálogo'!$E$6:$E$8,MATCH(H14,'Calibración del catálogo'!$A$6:$A$8,0)) -> Intermedio o superior | L14: =IFERROR(INDEX('Calibración del catálogo'!$L$16:$L$21,MATCH(A14,'Calibración del catálogo'!$H$16:$H$21,0)),INDEX('Calibración del catálogo'!$M$16:$M$21,MATCH(A14,'Calibración del catálogo'!$J$16:$J$21,0))) -> 0.81666667 | M14: =IFERROR(L14*INDEX(Demanda!$B$5:$B$10,MATCH(B14,Demanda!$A$5:$A$10,0)),"revisar") -> 0.032666667 | N14: Tramo superior de la distribución de la Tabla 3 (S15) | O14: ='Calibración del catálogo'!G32 -> 42.8 | Q14: ='Calibración del catálogo'!E32 -> 180 | R14: ='Calibración del catálogo'!F32 -> 0.18333333 | S14: 1 | T14: ='Calibración del catálogo'!I32 -> 111.4 | U14: =INDEX('Calibración del catálogo'!$H$6:$H$8,MATCH(H14,'Calibración del catálogo'!$A$6:$A$8,0)) -> 0.024932807 | V14: X | X14: X | Y14: X | Z14: X | AA14: Verificación con indio y muestra por duplicado o triplicado.
A15: M11 | B15: XRPD | C15: Identificación de la forma cristalina | D15: Patrón de difracción para confirmar la forma cristalina | E15: USP <941> | F15: Difractómetro de rayos X de polvo | G15: No | H15: media | I15: =INDEX('Calibración del catálogo'!$B$6:$B$8,MATCH(H15,'Calibración del catálogo'!$A$6:$A$8,0)) -> 3 | J15: =INDEX('Calibración del catálogo'!$C$6:$C$8,MATCH(H15,'Calibración del catálogo'!$A$6:$A$8,0)) -> 4 | K15: =INDEX('Calibración del catálogo'!$E$6:$E$8,MATCH(H15,'Calibración del catálogo'!$A$6:$A$8,0)) -> Intermedio o superior | L15: =IFERROR(INDEX('Calibración del catálogo'!$L$16:$L$21,MATCH(A15,'Calibración del catálogo'!$H$16:$H$21,0)),INDEX('Calibración del catálogo'!$M$16:$M$21,MATCH(A15,'Calibración del catálogo'!$J$16:$J$21,0))) -> 0.77857143 | M15: =IFERROR(L15*INDEX(Demanda!$B$5:$B$10,MATCH(B15,Demanda!$A$5:$A$10,0)),"revisar") -> 0.028807143 | N15: Tramo inferior de la distribución de la Tabla 3 (S15) | O15: ='Calibración del catálogo'!C33 -> 11 | Q15: ='Calibración del catálogo'!G33 -> 116.00837 | R15: 0 | S15: ='Calibración del catálogo'!F33 -> 0.77857143 | T15: ='Calibración del catálogo'!H33 -> 61.084039 | U15: =INDEX('Calibración del catálogo'!$H$6:$H$8,MATCH(H15,'Calibración del catálogo'!$A$6:$A$8,0)) -> 0.024932807 | V15: X | W15: X | Y15: X | AA15: Estándar de la forma y muestra por duplicado.
A16: M12 | B16: XRPD | C16: Cuantificación de fases | D16: Porcentaje de una forma no deseada o de material amorfo, con curva de calibración | E16: USP <941> | F16: Difractómetro de rayos X de polvo | G16: No | H16: alta | I16: =INDEX('Calibración del catálogo'!$B$6:$B$8,MATCH(H16,'Calibración del catálogo'!$A$6:$A$8,0)) -> 5 | J16: =INDEX('Calibración del catálogo'!$C$6:$C$8,MATCH(H16,'Calibración del catálogo'!$A$6:$A$8,0)) -> 6 | K16: =INDEX('Calibración del catálogo'!$E$6:$E$8,MATCH(H16,'Calibración del catálogo'!$A$6:$A$8,0)) -> Solo sénior | L16: =IFERROR(INDEX('Calibración del catálogo'!$L$16:$L$21,MATCH(A16,'Calibración del catálogo'!$H$16:$H$21,0)),INDEX('Calibración del catálogo'!$M$16:$M$21,MATCH(A16,'Calibración del catálogo'!$J$16:$J$21,0))) -> 0.22142857 | M16: =IFERROR(L16*INDEX(Demanda!$B$5:$B$10,MATCH(B16,Demanda!$A$5:$A$10,0)),"revisar") -> 0.0081928571 | N16: Tramo superior de la distribución de la Tabla 3 (S15) | O16: ='Calibración del catálogo'!G33 -> 116.00837 | Q16: ='Calibración del catálogo'!E33 -> 203 | R16: ='Calibración del catálogo'!F33 -> 0.77857143 | S16: 1 | T16: ='Calibración del catálogo'!I33 -> 145.00558 | U16: =INDEX('Calibración del catálogo'!$H$6:$H$8,MATCH(H16,'Calibración del catálogo'!$A$6:$A$8,0)) -> 0.049865613 | X16: X | Y16: X | Z16: X | AA16: Mezclas de calibración y muestras.

Sheet Calibración del catálogo
A1: Calibración del catálogo con las fuentes
A2: Cómo se calculan las columnas de la hoja Catálogo. Azul = dato de la fuente · negro = fórmula · amarillo = supuesto que pueden cambiar.
A4: A. Regla de complejidad (supuestos S11, S12 y S13)
A5: Nivel | B5: Soluciones mín | C5: Soluciones máx | D5: Media de soluciones | E5: Calificación mínima | F5: Multiplicador de reanálisis | G5: Participación en la demanda | H5: Prob. de reanálisis
A6: baja | B6: 1 | C6: 2 | D6: =(B6+C6)/2 -> 1.5 | E6: Júnior o superior | F6: 0.5 | G6: =SUMIFS(Catálogo!$M$5:$M$16,Catálogo!$H$5:$H$16,A6) -> 0.46310501 | H6: =IFERROR($B$11*F6/$B$12,"") -> 0.012466403
A7: media | B7: 3 | C7: 4 | D7: =(B7+C7)/2 -> 3.5 | E7: Intermedio o superior | F7: 1 | G7: =SUMIFS(Catálogo!$M$5:$M$16,Catálogo!$H$5:$H$16,A7) -> 0.50318651 | H7: =IFERROR($B$11*F7/$B$12,"") -> 0.024932807
A8: alta | B8: 5 | C8: 6 | D8: =(B8+C8)/2 -> 5.5 | E8: Solo sénior | F8: 2 | G8: =SUMIFS(Catálogo!$M$5:$M$16,Catálogo!$H$5:$H$16,A8) -> 0.033708482 | H8: =IFERROR($B$11*F8/$B$12,"") -> 0.049865613
A9: Total / promedio ponderado | G9: =SUM(G6:G8) -> 1 | H9: =SUMPRODUCT(G6:G8,H6:H8) -> 0.02
A11: Tasa base de reanálisis (S01) | B11: =Supuestos!$D$5 -> 0.02 | C11: Viene de la hoja Supuestos (S01); se cambia allá.
A12: Factor de normalización | B12: =SUMPRODUCT(F6:F8,G6:G8) -> 0.80215598 | C12: Promedio de los multiplicadores ponderado por la demanda. Con él, el promedio ponderado de la columna H (celda H9) queda igual a S01.
A14: B. Participación de cada método: soluciones promedio implícitas en Costigliola et al. (2017, Tabla 3, p. 9016, y Tabla 6, p. 9019)
A15: Técnica | B15: Prep. del análisis, Tabla 6 (min) | C15: Prep. por solución, Tabla 3: mín | D15: moda | E15: máx | F15: Media triangular por solución (min) | G15: Soluciones promedio implícitas | H15: Método simple | I15: Media de soluciones (simple) | J15: Método exigente | K15: Media de soluciones (exigente) | L15: Participación del simple | M15: Participación del exigente | N15: Prep. reproducida (min) | O15: Diferencia con Tabla 6 | P15: Prep. con BetaPERT estándar (min) | Q15: Diferencia con Tabla 6 | R15: Chequeo
A16: HPLC | B16: 96 | C16: =Duraciones!D5 -> 5 | D16: =Duraciones!E5 -> 40 | E16: =Duraciones!F5 -> 100 | F16: =(C16+D16+E16)/3 -> 48.333333 | G16: =B16/F16 -> 1.9862069 | H16: M01 | I16: =INDEX($D$6:$D$8,MATCH(INDEX(Catálogo!$H$5:$H$16,MATCH(H16,Catálogo!$A$5:$A$16,0)),$A$6:$A$8,0)) -> 1.5 | J16: M02 | K16: =INDEX($D$6:$D$8,MATCH(INDEX(Catálogo!$H$5:$H$16,MATCH(J16,Catálogo!$A$5:$A$16,0)),$A$6:$A$8,0)) -> 3.5 | L16: =IFERROR((K16-G16)/(K16-I16),"revisar") -> 0.75689655 | M16: =IFERROR(1-L16,"revisar") -> 0.24310345 | N16: =IFERROR((L16*I16+M16*K16)*F16,"") -> 96 | O16: =IFERROR(N16/B16-1,"") -> 0 | P16: =G16*(C16+4*D16+E16)/6 -> 87.724138 | Q16: =P16/B16-1 -> -0.086206897 | R16: =IF(ISNUMBER(L16),IF(AND(L16>=0,L16<=1),"OK","Revisar: el promedio no queda entre los dos métodos"),"Revisar: los dos métodos tienen la misma complejidad") -> OK
A17: GC | B17: 48 | C17: =Duraciones!D9 -> 5 | D17: =Duraciones!E9 -> 10 | E17: =Duraciones!F9 -> 35 | F17: =(C17+D17+E17)/3 -> 16.666667 | G17: =B17/F17 -> 2.88 | H17: M03 | I17: =INDEX($D$6:$D$8,MATCH(INDEX(Catálogo!$H$5:$H$16,MATCH(H17,Catálogo!$A$5:$A$16,0)),$A$6:$A$8,0)) -> 1.5 | J17: M04 | K17: =INDEX($D$6:$D$8,MATCH(INDEX(Catálogo!$H$5:$H$16,MATCH(J17,Catálogo!$A$5:$A$16,0)),$A$6:$A$8,0)) -> 3.5 | L17: =IFERROR((K17-G17)/(K17-I17),"revisar") -> 0.31 | M17: =IFERROR(1-L17,"revisar") -> 0.69 | N17: =IFERROR((L17*I17+M17*K17)*F17,"") -> 48 | O17: =IFERROR(N17/B17-1,"") -> 0 | P17: =G17*(C17+4*D17+E17)/6 -> 38.4 | Q17: =P17/B17-1 -> -0.2 | R17: =IF(ISNUMBER(L17),IF(AND(L17>=0,L17<=1),"OK","Revisar: el promedio no queda entre los dos métodos"),"Revisar: los dos métodos tienen la misma complejidad") -> OK
A18: PSA | B18: 31 | C18: =Duraciones!D13 -> 5 | D18: =Duraciones!E13 -> 7.5 | E18: =Duraciones!F13 -> 21 | F18: =(C18+D18+E18)/3 -> 11.166667 | G18: =B18/F18 -> 2.7761194 | H18: M05 | I18: =INDEX($D$6:$D$8,MATCH(INDEX(Catálogo!$H$5:$H$16,MATCH(H18,Catálogo!$A$5:$A$16,0)),$A$6:$A$8,0)) -> 1.5 | J18: M06 | K18: =INDEX($D$6:$D$8,MATCH(INDEX(Catálogo!$H$5:$H$16,MATCH(J18,Catálogo!$A$5:$A$16,0)),$A$6:$A$8,0)) -> 3.5 | L18: =IFERROR((K18-G18)/(K18-I18),"revisar") -> 0.3619403 | M18: =IFERROR(1-L18,"revisar") -> 0.6380597 | N18: =IFERROR((L18*I18+M18*K18)*F18,"") -> 31 | O18: =IFERROR(N18/B18-1,"") -> 0 | P18: =G18*(C18+4*D18+E18)/6 -> 25.910448 | Q18: =P18/B18-1 -> -0.1641791 | R18: =IF(ISNUMBER(L18),IF(AND(L18>=0,L18<=1),"OK","Revisar: el promedio no queda entre los dos métodos"),"Revisar: los dos métodos tienen la misma complejidad") -> OK
A19: KF | B19: 45 | C19: =Duraciones!D17 -> 1 | D19: =Duraciones!E17 -> 6 | E19: =Duraciones!F17 -> 25 | F19: =(C19+D19+E19)/3 -> 10.666667 | G19: =B19/F19 -> 4.21875 | H19: M07 | I19: =INDEX($D$6:$D$8,MATCH(INDEX(Catálogo!$H$5:$H$16,MATCH(H19,Catálogo!$A$5:$A$16,0)),$A$6:$A$8,0)) -> 3.5 | J19: M08 | K19: =INDEX($D$6:$D$8,MATCH(INDEX(Catálogo!$H$5:$H$16,MATCH(J19,Catálogo!$A$5:$A$16,0)),$A$6:$A$8,0)) -> 5.5 | L19: =IFERROR((K19-G19)/(K19-I19),"revisar") -> 0.640625 | M19: =IFERROR(1-L19,"revisar") -> 0.359375 | N19: =IFERROR((L19*I19+M19*K19)*F19,"") -> 45 | O19: =IFERROR(N19/B19-1,"") -> 0 | P19: =G19*(C19+4*D19+E19)/6 -> 35.15625 | Q19: =P19/B19-1 -> -0.21875 | R19: =IF(ISNUMBER(L19),IF(AND(L19>=0,L19<=1),"OK","Revisar: el promedio no queda entre los dos métodos"),"Revisar: los dos métodos tienen la misma complejidad") -> OK
A20: DSC | B20: 47 | C20: =Duraciones!D21 -> 5 | D20: =Duraciones!E21 -> 10 | E20: =Duraciones!F21 -> 30 | F20: =(C20+D20+E20)/3 -> 15 | G20: =B20/F20 -> 3.1333333 | H20: M09 | I20: =INDEX($D$6:$D$8,MATCH(INDEX(Catálogo!$H$5:$H$16,MATCH(H20,Catálogo!$A$5:$A$16,0)),$A$6:$A$8,0)) -> 1.5 | J20: M10 | K20: =INDEX($D$6:$D$8,MATCH(INDEX(Catálogo!$H$5:$H$16,MATCH(J20,Catálogo!$A$5:$A$16,0)),$A$6:$A$8,0)) -> 3.5 | L20: =IFERROR((K20-G20)/(K20-I20),"revisar") -> 0.18333333 | M20: =IFERROR(1-L20,"revisar") -> 0.81666667 | N20: =IFERROR((L20*I20+M20*K20)*F20,"") -> 47 | O20: =IFERROR(N20/B20-1,"") -> 0 | P20: =G20*(C20+4*D20+E20)/6 -> 39.166667 | Q20: =P20/B20-1 -> -0.16666667 | R20: =IF(ISNUMBER(L20),IF(AND(L20>=0,L20<=1),"OK","Revisar: el promedio no queda entre los dos métodos"),"Revisar: los dos métodos tienen la misma complejidad") -> OK
A21: XRPD | B21: 46 | C21: =Duraciones!D25 -> 5 | D21: =Duraciones!E25 -> 10 | E21: =Duraciones!F25 -> 20 | F21: =(C21+D21+E21)/3 -> 11.666667 | G21: =B21/F21 -> 3.9428571 | H21: M11 | I21: =INDEX($D$6:$D$8,MATCH(INDEX(Catálogo!$H$5:$H$16,MATCH(H21,Catálogo!$A$5:$A$16,0)),$A$6:$A$8,0)) -> 3.5 | J21: M12 | K21: =INDEX($D$6:$D$8,MATCH(INDEX(Catálogo!$H$5:$H$16,MATCH(J21,Catálogo!$A$5:$A$16,0)),$A$6:$A$8,0)) -> 5.5 | L21: =IFERROR((K21-G21)/(K21-I21),"revisar") -> 0.77857143 | M21: =IFERROR(1-L21,"revisar") -> 0.22142857 | N21: =IFERROR((L21*I21+M21*K21)*F21,"") -> 46 | O21: =IFERROR(N21/B21-1,"") -> 0 | P21: =G21*(C21+4*D21+E21)/6 -> 42.714286 | Q21: =P21/B21-1 -> -0.071428571 | R21: =IF(ISNUMBER(L21),IF(AND(L21>=0,L21<=1),"OK","Revisar: el promedio no queda entre los dos métodos"),"Revisar: los dos métodos tienen la misma complejidad") -> OK
A22: Soluciones promedio implícitas = prep. del análisis (Tabla 6) ÷ media triangular de la prep. por solución (Tabla 3), porque la fuente multiplica una por la otra (p. 9019). La participación del simple sale de igualar el promedio ponderado de los dos métodos a ese valor.
A23: C. Corrida de HPLC y GC: fija por método en la fuente y no publicada; se reparte el promedio de la Tabla 6 (supuestos S05 y S14)
A24: Técnica | B24: Corrida promedio, Tabla 6 (min) | C24: Relación exigente / simple | D24: Margen ± (S05) | E24: Moda del simple (min) | F24: Moda del exigente (min) | G24: Promedio ponderado (min) | H24: Diferencia con Tabla 6
A25: HPLC | B25: 85 | C25: 2.5 | D25: 0.2 | E25: =IFERROR(B25/(L16+M16*C25),"revisar") -> 62.286797 | F25: =IFERROR(C25*E25,"revisar") -> 155.71699 | G25: =IFERROR(L16*E25+M16*F25,"revisar") -> 85 | H25: =IFERROR(G25/B25-1,"revisar") -> 0
A26: GC | B26: 62 | C26: 1.5 | D26: =D25 -> 0.2 | E26: =IFERROR(B26/(L17+M17*C26),"revisar") -> 46.096654 | F26: =IFERROR(C26*E26,"revisar") -> 69.144981 | G26: =IFERROR(L17*E26+M17*F26,"revisar") -> 62 | H26: =IFERROR(G26/B26-1,"revisar") -> 0
A28: D. Corrida de PSA, KF, DSC y XRPD: la distribución de la Tabla 3 se reparte en dos tramos según la participación de cada método (supuesto S15)
A29: Técnica | B29: Distribución (Tabla 3) | C29: mín | D29: moda | E29: máx | F29: Participación del simple (cuantil de corte) | G29: Corte (min) | H29: Media del tramo simple (min) | I29: Media del tramo exigente (min) | J29: Promedio ponderado (min) | K29: Media de la distribución (min) | L29: Diferencia | M29: Auxiliar: G(moda) | N29: Auxiliar: G(corte) | O29: Auxiliar: G(máx)
A30: PSA | B30: T | C30: =Duraciones!D15 -> 5 | D30: =Duraciones!E15 -> 10 | E30: =Duraciones!F15 -> 30 | F30: =L18 -> 0.3619403 | G30: =IFERROR(IF(B30="U",C30+F30*(E30-C30),IF(F30<=(D30-C30)/(E30-C30),C30+SQRT(F30*(E30-C30)*(D30-C30)),E30-SQRT((1-F30)*(E30-C30)*(E30-D30)))),"revisar") -> 12.138593 | H30: =IFERROR(IF(B30="U",(C30+G30)/2,N30/F30),"revisar") -> 9.5484574 | I30: =IFERROR(IF(B30="U",(G30+E30)/2,(O30-N30)/(1-F30)),"revisar") -> 18.092396 | J30: =IFERROR(F30*H30+(1-F30)*I30,"revisar") -> 15 | K30: =IFERROR(IF(B30="U",(C30+E30)/2,(C30+D30+E30)/3),"revisar") -> 15 | L30: =IFERROR(J30/K30-1,"revisar") -> 0 | M30: =IFERROR(IF(B30="U","",2/((E30-C30)*(D30-C30))*(D30^3/3-C30*D30^2/2+C30^3/6)),"revisar") -> 1.6666667 | N30: =IFERROR(IF(B30="U","",IF(G30<=D30,2/((E30-C30)*(D30-C30))*(G30^3/3-C30*G30^2/2+C30^3/6),M30+2/((E30-C30)*(E30-D30))*(E30*G30^2/2-G30^3/3-E30*D30^2/2+D30^3/3))),"revisar") -> 3.4559715 | O30: =IFERROR(IF(B30="U","",M30+2/((E30-C30)*(E30-D30))*(E30^3/2-E30^3/3-E30*D30^2/2+D30^3/3)),"revisar") -> 15
A31: KF | B31: T | C31: =Duraciones!D19 -> 2 | D31: =Duraciones!E19 -> 5 | E31: =Duraciones!F19 -> 56 | F31: =L19 -> 0.640625 | G31: =IFERROR(IF(B31="U",C31+F31*(E31-C31),IF(F31<=(D31-C31)/(E31-C31),C31+SQRT(F31*(E31-C31)*(D31-C31)),E31-SQRT((1-F31)*(E31-C31)*(E31-D31)))),"revisar") -> 24.540204 | H31: =IFERROR(IF(B31="U",(C31+G31)/2,N31/F31),"revisar") -> 13.131306 | I31: =IFERROR(IF(B31="U",(G31+E31)/2,(O31-N31)/(1-F31)),"revisar") -> 35.026803 | J31: =IFERROR(F31*H31+(1-F31)*I31,"revisar") -> 21 | K31: =IFERROR(IF(B31="U",(C31+E31)/2,(C31+D31+E31)/3),"revisar") -> 21 | L31: =IFERROR(J31/K31-1,"revisar") -> 0 | M31: =IFERROR(IF(B31="U","",2/((E31-C31)*(D31-C31))*(D31^3/3-C31*D31^2/2+C31^3/6)),"revisar") -> 0.22222222 | N31: =IFERROR(IF(B31="U","",IF(G31<=D31,2/((E31-C31)*(D31-C31))*(G31^3/3-C31*G31^2/2+C31^3/6),M31+2/((E31-C31)*(E31-D31))*(E31*G31^2/2-G31^3/3-E31*D31^2/2+D31^3/3))),"revisar") -> 8.4122427 | O31: =IFERROR(IF(B31="U","",M31+2/((E31-C31)*(E31-D31))*(E31^3/2-E31^3/3-E31*D31^2/2+D31^3/3)),"revisar") -> 21
A32: DSC | B32: U | C32: =Duraciones!D23 -> 12 | D32: =Duraciones!E23 -> 96 | E32: =Duraciones!F23 -> 180 | F32: =L20 -> 0.18333333 | G32: =IFERROR(IF(B32="U",C32+F32*(E32-C32),IF(F32<=(D32-C32)/(E32-C32),C32+SQRT(F32*(E32-C32)*(D32-C32)),E32-SQRT((1-F32)*(E32-C32)*(E32-D32)))),"revisar") -> 42.8 | H32: =IFERROR(IF(B32="U",(C32+G32)/2,N32/F32),"revisar") -> 27.4 | I32: =IFERROR(IF(B32="U",(G32+E32)/2,(O32-N32)/(1-F32)),"revisar") -> 111.4 | J32: =IFERROR(F32*H32+(1-F32)*I32,"revisar") -> 96 | K32: =IFERROR(IF(B32="U",(C32+E32)/2,(C32+D32+E32)/3),"revisar") -> 96 | L32: =IFERROR(J32/K32-1,"revisar") -> 0 | M32: =IFERROR(IF(B32="U","",2/((E32-C32)*(D32-C32))*(D32^3/3-C32*D32^2/2+C32^3/6)),"revisar") | N32: =IFERROR(IF(B32="U","",IF(G32<=D32,2/((E32-C32)*(D32-C32))*(G32^3/3-C32*G32^2/2+C32^3/6),M32+2/((E32-C32)*(E32-D32))*(E32*G32^2/2-G32^3/3-E32*D32^2/2+D32^3/3))),"revisar") | O32: =IFERROR(IF(B32="U","",M32+2/((E32-C32)*(E32-D32))*(E32^3/2-E32^3/3-E32*D32^2/2+D32^3/3)),"revisar")
A33: XRPD | B33: T | C33: =Duraciones!D27 -> 11 | D33: =Duraciones!E27 -> 25 | E33: =Duraciones!F27 -> 203 | F33: =L21 -> 0.77857143 | G33: =IFERROR(IF(B33="U",C33+F33*(E33-C33),IF(F33<=(D33-C33)/(E33-C33),C33+SQRT(F33*(E33-C33)*(D33-C33)),E33-SQRT((1-F33)*(E33-C33)*(E33-D33)))),"revisar") -> 116.00837 | H33: =IFERROR(IF(B33="U",(C33+G33)/2,N33/F33),"revisar") -> 61.084039 | I33: =IFERROR(IF(B33="U",(G33+E33)/2,(O33-N33)/(1-F33)),"revisar") -> 145.00558 | J33: =IFERROR(F33*H33+(1-F33)*I33,"revisar") -> 79.666667 | K33: =IFERROR(IF(B33="U",(C33+E33)/2,(C33+D33+E33)/3),"revisar") -> 79.666667 | L33: =IFERROR(J33/K33-1,"revisar") -> 0 | M33: =IFERROR(IF(B33="U","",2/((E33-C33)*(D33-C33))*(D33^3/3-C33*D33^2/2+C33^3/6)),"revisar") -> 1.4826389 | N33: =IFERROR(IF(B33="U","",IF(G33<=D33,2/((E33-C33)*(D33-C33))*(G33^3/3-C33*G33^2/2+C33^3/6),M33+2/((E33-C33)*(E33-D33))*(E33*G33^2/2-G33^3/3-E33*D33^2/2+D33^3/3))),"revisar") -> 47.558288 | O33: =IFERROR(IF(B33="U","",M33+2/((E33-C33)*(E33-D33))*(E33^3/2-E33^3/3-E33*D33^2/2+D33^3/3)),"revisar") -> 79.666667
A35: G(x) es el momento parcial de la triangular entre el mínimo y x (integral de t·f(t)); la media de cada tramo es la diferencia de G entre sus extremos dividida por la probabilidad del tramo. En la uniforme (DSC) la media del tramo es su punto medio.
A36: Los cortes en minutos usan la distribución de la fuente (triangular o uniforme). Si el generador usa BetaPERT, se aplica el mismo cuantil sobre la BetaPERT.
A37: «Prep. con BetaPERT estándar» (bloque B) muestra cuánto bajaría la preparación promedio si el generador usa BetaPERT con λ = 4 en lugar de la triangular de la fuente (Léeme, Ojo 4).

Sheet Tipos de muestra
A1: Tipos de muestra del laboratorio de referencia
A2: Una fila por tipo. Amarillo = decisión (proporción, llegadas, plazos y urgentes); la probabilidad de cada método dentro del tipo (columnas M01 a M12) se calcula en la hoja Calibración de tipos.
A3: Definiciones: WHO (2014, glosario, pp. 82–85). Llegadas: Costigliola et al. (2017, p. 9015) y supuesto S10. Plazos: Costigliola et al. (2017, p. 9018) y supuesto S06. Volumen: Tabla 4 de Costigliola et al. (2017) y ensayos por muestra de Cunha et al. (2019), en la hoja Demanda.
A4: Código | B4: Tipo de muestra | C4: Definición | D4: Proporción de muestras | E4: Días de llegada por semana | F4: Llegada desde (h) | G4: Llegada hasta (h) | H4: Forma de llegada | I4: Plazo | J4: Unidad del plazo | K4: Plazo en horas (aprox.) | L4: Prioridad | M4: Puede ser urgente | N4: Muestras al año | O4: Muestras por día de llegada | P4: M01 | Q4: M02 | R4: M03 | S4: M04 | T4: M05 | U4: M06 | V4: M07 | W4: M08 | X4: M09 | Y4: M10 | Z4: M11 | AA4: M12 | AB4: Fuente o supuesto
A5: MP | B5: Materia prima | C5: Sustancia de calidad definida que se usa en la producción de un producto farmacéutico, excepto los materiales de empaque. | D5: 0.25 | E5: 5 | F5: 8 | G5: 17 | H5: Poisson | I5: 5 | J5: días hábiles | K5: =IF(J5="h",I5,I5*24) -> 120 | L5: =RANK(K5,$K$5:$K$9,1) -> 4 | M5: Sí | N5: =D5*Demanda!$C$11/Demanda!$C$22 -> 3192.2917 | O5: =N5/IF(E5=7,Demanda!$B$14,Demanda!$B$15) -> 12.278045 | P5: ='Calibración de tipos'!C58 -> 0.17395194 | Q5: ='Calibración de tipos'!D58 -> 0.095116665 | R5: ='Calibración de tipos'!E58 -> 0.31868 | S5: ='Calibración de tipos'!F58 -> 0.12154841 | T5: ='Calibración de tipos'!G58 -> 0.059759521 | U5: ='Calibración de tipos'!H58 -> 0.11531618 | V5: ='Calibración de tipos'!I58 -> 0.025683876 | W5: ='Calibración de tipos'!J58 -> 0.028919842 | ... AA5: ='Calibración de tipos'!N58 -> 0 | AB5: Definición: WHO (2014, p. 85). Baja prioridad: puede procesarse incluso después de una semana (Costigliola et al., 2017, p. 9018).
